2023-08-10T22:07:09Z [INFO] [31m[1mWARNING: This is a development server. Do not use it in a production deployment. Use a production WSGI server instead.[0m
 * Running on http://127.0.0.1:5000
2023-08-10T22:07:09Z [INFO] [33mPress CTRL+C to quit[0m
2023-08-10T22:07:15Z [WARNING] No hostname was supplied. Reverting to default 'localhost'
2023-08-10T22:07:21Z [INFO] 127.0.0.1 - - [10/Aug/2023 22:07:21] "[35m[1mPOST /scheduler/refactor?&worker_name=worker1 HTTP/1.1[0m" 500 -
2023-08-10T22:07:21Z [ERROR] Error on request:
Traceback (most recent call last):
  File "/home/rbouazizi/.cache/pypoetry/virtualenvs/tgb-bot-IKtkagiw-py3.10/lib/python3.10/site-packages/kombu/utils/functional.py", line 32, in __call__
    return self.__value__
AttributeError: 'ChannelPromise' object has no attribute '__value__'

During handling of the above exception, another exception occurred:

Traceback (most recent call last):
  File "/home/rbouazizi/.cache/pypoetry/virtualenvs/tgb-bot-IKtkagiw-py3.10/lib/python3.10/site-packages/kombu/connection.py", line 472, in _reraise_as_library_errors
    yield
  File "/home/rbouazizi/.cache/pypoetry/virtualenvs/tgb-bot-IKtkagiw-py3.10/lib/python3.10/site-packages/kombu/connection.py", line 459, in _ensure_connection
    return retry_over_time(
  File "/home/rbouazizi/.cache/pypoetry/virtualenvs/tgb-bot-IKtkagiw-py3.10/lib/python3.10/site-packages/kombu/utils/functional.py", line 318, in retry_over_time
    return fun(*args, **kwargs)
  File "/home/rbouazizi/.cache/pypoetry/virtualenvs/tgb-bot-IKtkagiw-py3.10/lib/python3.10/site-packages/kombu/connection.py", line 941, in _connection_factory
    self._connection = self._establish_connection()
  File "/home/rbouazizi/.cache/pypoetry/virtualenvs/tgb-bot-IKtkagiw-py3.10/lib/python3.10/site-packages/kombu/connection.py", line 867, in _establish_connection
    conn = self.transport.establish_connection()
  File "/home/rbouazizi/.cache/pypoetry/virtualenvs/tgb-bot-IKtkagiw-py3.10/lib/python3.10/site-packages/kombu/transport/pyamqp.py", line 203, in establish_connection
    conn.connect()
  File "/home/rbouazizi/.cache/pypoetry/virtualenvs/tgb-bot-IKtkagiw-py3.10/lib/python3.10/site-packages/amqp/connection.py", line 323, in connect
    self.transport.connect()
  File "/home/rbouazizi/.cache/pypoetry/virtualenvs/tgb-bot-IKtkagiw-py3.10/lib/python3.10/site-packages/amqp/transport.py", line 129, in connect
    self._connect(self.host, self.port, self.connect_timeout)
  File "/home/rbouazizi/.cache/pypoetry/virtualenvs/tgb-bot-IKtkagiw-py3.10/lib/python3.10/site-packages/amqp/transport.py", line 184, in _connect
    self.sock.connect(sa)
ConnectionRefusedError: [Errno 111] Connection refused

The above exception was the direct cause of the following exception:

Traceback (most recent call last):
  File "/home/rbouazizi/.cache/pypoetry/virtualenvs/tgb-bot-IKtkagiw-py3.10/lib/python3.10/site-packages/werkzeug/serving.py", line 364, in run_wsgi
    execute(self.server.app)
  File "/home/rbouazizi/.cache/pypoetry/virtualenvs/tgb-bot-IKtkagiw-py3.10/lib/python3.10/site-packages/werkzeug/serving.py", line 325, in execute
    application_iter = app(environ, start_response)
  File "/home/rbouazizi/.cache/pypoetry/virtualenvs/tgb-bot-IKtkagiw-py3.10/lib/python3.10/site-packages/flask/app.py", line 2213, in __call__
    return self.wsgi_app(environ, start_response)
  File "/home/rbouazizi/.cache/pypoetry/virtualenvs/tgb-bot-IKtkagiw-py3.10/lib/python3.10/site-packages/flask/app.py", line 2193, in wsgi_app
    response = self.handle_exception(e)
  File "/home/rbouazizi/.cache/pypoetry/virtualenvs/tgb-bot-IKtkagiw-py3.10/lib/python3.10/site-packages/flask/app.py", line 2190, in wsgi_app
    response = self.full_dispatch_request()
  File "/home/rbouazizi/.cache/pypoetry/virtualenvs/tgb-bot-IKtkagiw-py3.10/lib/python3.10/site-packages/flask/app.py", line 1486, in full_dispatch_request
    rv = self.handle_user_exception(e)
  File "/home/rbouazizi/.cache/pypoetry/virtualenvs/tgb-bot-IKtkagiw-py3.10/lib/python3.10/site-packages/flask/app.py", line 1484, in full_dispatch_request
    rv = self.dispatch_request()
  File "/home/rbouazizi/.cache/pypoetry/virtualenvs/tgb-bot-IKtkagiw-py3.10/lib/python3.10/site-packages/flask/app.py", line 1469, in dispatch_request
    return self.ensure_sync(self.view_functions[rule.endpoint])(**view_args)
  File "/home/rbouazizi/telegram-bot/tgb_bot/src/tgb_bot/bot_task_routes.py", line 11, in refactor
    result = listen_to_messages.apply_async(args=[conn_id, mode], queue="refactor")
  File "/home/rbouazizi/.cache/pypoetry/virtualenvs/tgb-bot-IKtkagiw-py3.10/lib/python3.10/site-packages/celery/app/task.py", line 594, in apply_async
    return app.send_task(
  File "/home/rbouazizi/.cache/pypoetry/virtualenvs/tgb-bot-IKtkagiw-py3.10/lib/python3.10/site-packages/celery/app/base.py", line 798, in send_task
    amqp.send_task_message(P, name, message, **options)
  File "/home/rbouazizi/.cache/pypoetry/virtualenvs/tgb-bot-IKtkagiw-py3.10/lib/python3.10/site-packages/celery/app/amqp.py", line 517, in send_task_message
    ret = producer.publish(
  File "/home/rbouazizi/.cache/pypoetry/virtualenvs/tgb-bot-IKtkagiw-py3.10/lib/python3.10/site-packages/kombu/messaging.py", line 186, in publish
    return _publish(
  File "/home/rbouazizi/.cache/pypoetry/virtualenvs/tgb-bot-IKtkagiw-py3.10/lib/python3.10/site-packages/kombu/connection.py", line 563, in _ensured
    return fun(*args, **kwargs)
  File "/home/rbouazizi/.cache/pypoetry/virtualenvs/tgb-bot-IKtkagiw-py3.10/lib/python3.10/site-packages/kombu/messaging.py", line 195, in _publish
    channel = self.channel
  File "/home/rbouazizi/.cache/pypoetry/virtualenvs/tgb-bot-IKtkagiw-py3.10/lib/python3.10/site-packages/kombu/messaging.py", line 218, in _get_channel
    channel = self._channel = channel()
  File "/home/rbouazizi/.cache/pypoetry/virtualenvs/tgb-bot-IKtkagiw-py3.10/lib/python3.10/site-packages/kombu/utils/functional.py", line 34, in __call__
    value = self.__value__ = self.__contract__()
  File "/home/rbouazizi/.cache/pypoetry/virtualenvs/tgb-bot-IKtkagiw-py3.10/lib/python3.10/site-packages/kombu/messaging.py", line 234, in <lambda>
    channel = ChannelPromise(lambda: connection.default_channel)
  File "/home/rbouazizi/.cache/pypoetry/virtualenvs/tgb-bot-IKtkagiw-py3.10/lib/python3.10/site-packages/kombu/connection.py", line 960, in default_channel
    self._ensure_connection(**conn_opts)
  File "/home/rbouazizi/.cache/pypoetry/virtualenvs/tgb-bot-IKtkagiw-py3.10/lib/python3.10/site-packages/kombu/connection.py", line 458, in _ensure_connection
    with ctx():
  File "/usr/lib/python3.10/contextlib.py", line 153, in __exit__
    self.gen.throw(typ, value, traceback)
  File "/home/rbouazizi/.cache/pypoetry/virtualenvs/tgb-bot-IKtkagiw-py3.10/lib/python3.10/site-packages/kombu/connection.py", line 476, in _reraise_as_library_errors
    raise ConnectionError(str(exc)) from exc
kombu.exceptions.OperationalError: [Errno 111] Connection refused
